Workbook

Sheet DASHBOARD
A1: VESSEL CLEARANCE STATUS REPORT - NMDPRA CARGO CLEARANCE
A2: ="Vessel clearance dashboard | Report date: "&TEXT(TODAY(),"dd mmmm yyyy") | G2: ="Report date: "&TEXT(TODAY(),"dd mmmm yyyy")
A5: TOTAL VESSELS | C5: CLEARED | E5: PENDING | G5: % CLEARED | I5: QTY PENDING (MT) | K5: OLDEST PENDING (DAYS)
A6: =COUNTIF('VESSEL REGISTER'!$H$6:$H$105,"CLEARED")+COUNTIF('VESSEL REGISTER'!$H$6:$H$105,"PENDING") | C6: =COUNTIF('VESSEL REGISTER'!$H$6:$H$105,"CLEARED") | E6: =COUNTIF('VESSEL REGISTER'!$H$6:$H$105,"PENDING") | G6: =IF(A6=0,0,C6/A6) | I6: =SUMIFS('VESSEL REGISTER'!$F$6:$F$105,'VESSEL REGISTER'!$H$6:$H$105,"PENDING") | K6: =IFERROR(INDEX('VESSEL REGISTER'!$I$6:$I$105,MATCH(1,'VESSEL REGISTER'!$O$6:$O$105,0)),0)
A7: all vessels logged | C7: NMDPRA clearance received | E7: awaiting clearance | G7: cleared / total | I7: tonnage not yet cleared | K7: longest wait so far
A9: QTY CLEARED (MT) | C9: CRITICAL PENDING | E9: NEED ATTENTION | G9: AVG DAYS TO CLEAR | I9: CLEARED THIS MONTH | K9: NEW VESSELS THIS MONTH
A10: =SUMIFS('VESSEL REGISTER'!$F$6:$F$105,'VESSEL REGISTER'!$H$6:$H$105,"CLEARED") | C10: =COUNTIF('VESSEL REGISTER'!$J$6:$J$105,"CRITICAL") | E10: =COUNTIF('VESSEL REGISTER'!$J$6:$J$105,"ATTENTION") | G10: =IFERROR(AVERAGEIFS('VESSEL REGISTER'!$I$6:$I$105,'VESSEL REGISTER'!$H$6:$H$105,"CLEARED"),0) | I10: =COUNTIFS('VESSEL REGISTER'!$G$6:$G$105,">="&DATE(YEAR(TODAY()),MONTH(TODAY()),1),'VESSEL REGISTER'!$G$6:$G$105,"<"&DATE(YEAR(TODAY()),MONTH(TODAY())+1,1)) | K10: =COUNTIFS('VESSEL REGISTER'!$E$6:$E$105,">="&DATE(YEAR(TODAY()),MONTH(TODAY()),1),'VESSEL REGISTER'!$E$6:$E$105,"<"&DATE(YEAR(TODAY()),MONTH(TODAY())+1,1))
A11: tonnage cleared | C11: over critical limit | E11: over attention limit | G11: cleared vessels only | I11: clearances in current month | K11: started in current month
A13: CLEARANCE STATUS BY PRODUCT | I13: PENDING VESSELS BY AGEING
A14: Product | B14: Vessels | C14: Cleared | D14: Pending | E14: % Cleared | F14: Qty Cleared (MT) | G14: Qty Pending (MT) | I14: Days pending | J14: Vessels | K14: Qty (MT) | L14: % of pending
A15: AGO | B15: =C15+D15 | C15: =COUNTIFS('VESSEL REGISTER'!$C$6:$C$105,A15,'VESSEL REGISTER'!$H$6:$H$105,"CLEARED") | D15: =COUNTIFS('VESSEL REGISTER'!$C$6:$C$105,A15,'VESSEL REGISTER'!$H$6:$H$105,"PENDING") | E15: =IF(B15=0,0,C15/B15) | F15: =SUMIFS('VESSEL REGISTER'!$F$6:$F$105,'VESSEL REGISTER'!$C$6:$C$105,A15,'VESSEL REGISTER'!$H$6:$H$105,"CLEARED") | G15: =SUMIFS('VESSEL REGISTER'!$F$6:$F$105,'VESSEL REGISTER'!$C$6:$C$105,A15,'VESSEL REGISTER'!$H$6:$H$105,"PENDING") | I15: 0 - 7 days | J15: =COUNTIFS('VESSEL REGISTER'!$H$6:$H$105,"PENDING",'VESSEL REGISTER'!$I$6:$I$105,">=0",'VESSEL REGISTER'!$I$6:$I$105,"<=7") | K15: =SUMIFS('VESSEL REGISTER'!$F$6:$F$105,'VESSEL REGISTER'!$H$6:$H$105,"PENDING",'VESSEL REGISTER'!$I$6:$I$105,">=0",'VESSEL REGISTER'!$I$6:$I$105,"<=7") | L15: =IF($E$6=0,0,J15/$E$6)
A16: PMS | B16: =C16+D16 | C16: =COUNTIFS('VESSEL REGISTER'!$C$6:$C$105,A16,'VESSEL REGISTER'!$H$6:$H$105,"CLEARED") | D16: =COUNTIFS('VESSEL REGISTER'!$C$6:$C$105,A16,'VESSEL REGISTER'!$H$6:$H$105,"PENDING") | E16: =IF(B16=0,0,C16/B16) | F16: =SUMIFS('VESSEL REGISTER'!$F$6:$F$105,'VESSEL REGISTER'!$C$6:$C$105,A16,'VESSEL REGISTER'!$H$6:$H$105,"CLEARED") | G16: =SUMIFS('VESSEL REGISTER'!$F$6:$F$105,'VESSEL REGISTER'!$C$6:$C$105,A16,'VESSEL REGISTER'!$H$6:$H$105,"PENDING") | I16: 8 - 14 days | J16: =COUNTIFS('VESSEL REGISTER'!$H$6:$H$105,"PENDING",'VESSEL REGISTER'!$I$6:$I$105,">=8",'VESSEL REGISTER'!$I$6:$I$105,"<=14") | K16: =SUMIFS('VESSEL REGISTER'!$F$6:$F$105,'VESSEL REGISTER'!$H$6:$H$105,"PENDING",'VESSEL REGISTER'!$I$6:$I$105,">=8",'VESSEL REGISTER'!$I$6:$I$105,"<=14") | L16: =IF($E$6=0,0,J16/$E$6)
A17: TOTAL | B17: =SUM(B15:B16) | C17: =SUM(C15:C16) | D17: =SUM(D15:D16) | E17: =IF(B17=0,0,C17/B17) | F17: =SUM(F15:F16) | G17: =SUM(G15:G16) | I17: 15 - 30 days | J17: =COUNTIFS('VESSEL REGISTER'!$H$6:$H$105,"PENDING",'VESSEL REGISTER'!$I$6:$I$105,">=15",'VESSEL REGISTER'!$I$6:$I$105,"<=30") | K17: =SUMIFS('VESSEL REGISTER'!$F$6:$F$105,'VESSEL REGISTER'!$H$6:$H$105,"PENDING",'VESSEL REGISTER'!$I$6:$I$105,">=15",'VESSEL REGISTER'!$I$6:$I$105,"<=30") | L17: =IF($E$6=0,0,J17/$E$6)
I18: Over 30 days | J18: =COUNTIFS('VESSEL REGISTER'!$H$6:$H$105,"PENDING",'VESSEL REGISTER'!$I$6:$I$105,">30") | K18: =SUMIFS('VESSEL REGISTER'!$F$6:$F$105,'VESSEL REGISTER'!$H$6:$H$105,"PENDING",'VESSEL REGISTER'!$I$6:$I$105,">30") | L18: =IF($E$6=0,0,J18/$E$6)
I19: TOTAL PENDING | J19: =SUM(J15:J18) | K19: =SUM(K15:K18) | L19: =SUM(L15:L18)
A21: WHY ARE VESSELS PENDING? | I21: MONTHLY TREND (LAST 6 MONTHS)
A22: Pending reason | D22: Vessels | E22: Qty (MT) | F22: % of pending | G22: Oldest (days) | I22: Month | J22: Vessels started | K22: Vessels cleared | L22: Qty cleared (MT)
A23: ='GUIDE & SETTINGS'!F4 | D23: =COUNTIFS('VESSEL REGISTER'!$H$6:$H$105,"PENDING",'VESSEL REGISTER'!$K$6:$K$105,A23) | E23: =SUMIFS('VESSEL REGISTER'!$F$6:$F$105,'VESSEL REGISTER'!$H$6:$H$105,"PENDING",'VESSEL REGISTER'!$K$6:$K$105,A23) | F23: =IF($E$6=0,0,D23/$E$6) | G23: =IF(D23=0,0,SUMPRODUCT(MAX(('VESSEL REGISTER'!$H$6:$H$105="PENDING")*('VESSEL REGISTER'!$K$6:$K$105=A23)*N(+'VESSEL REGISTER'!$I$6:$I$105)))) | I23: =TEXT(DATE(YEAR(TODAY()),MONTH(TODAY())-5,1),"mmm yy") | J23: =COUNTIFS('VESSEL REGISTER'!$E$6:$E$105,">="&DATE(YEAR(TODAY()),MONTH(TODAY())-5,1),'VESSEL REGISTER'!$E$6:$E$105,"<"&DATE(YEAR(TODAY()),MONTH(TODAY())-4,1)) | K23: =COUNTIFS('VESSEL REGISTER'!$G$6:$G$105,">="&DATE(YEAR(TODAY()),MONTH(TODAY())-5,1),'VESSEL REGISTER'!$G$6:$G$105,"<"&DATE(YEAR(TODAY()),MONTH(TODAY())-4,1)) | L23: =SUMIFS('VESSEL REGISTER'!$F$6:$F$105,'VESSEL REGISTER'!$G$6:$G$105,">="&DATE(YEAR(TODAY()),MONTH(TODAY())-5,1),'VESSEL REGISTER'!$G$6:$G$105,"<"&DATE(YEAR(TODAY()),MONTH(TODAY())-4,1))
A24: ='GUIDE & SETTINGS'!F5 | D24: =COUNTIFS('VESSEL REGISTER'!$H$6:$H$105,"PENDING",'VESSEL REGISTER'!$K$6:$K$105,A24) | E24: =SUMIFS('VESSEL REGISTER'!$F$6:$F$105,'VESSEL REGISTER'!$H$6:$H$105,"PENDING",'VESSEL REGISTER'!$K$6:$K$105,A24) | F24: =IF($E$6=0,0,D24/$E$6) | G24: =IF(D24=0,0,SUMPRODUCT(MAX(('VESSEL REGISTER'!$H$6:$H$105="PENDING")*('VESSEL REGISTER'!$K$6:$K$105=A24)*N(+'VESSEL REGISTER'!$I$6:$I$105)))) | I24: =TEXT(DATE(YEAR(TODAY()),MONTH(TODAY())-4,1),"mmm yy") | J24: =COUNTIFS('VESSEL REGISTER'!$E$6:$E$105,">="&DATE(YEAR(TODAY()),MONTH(TODAY())-4,1),'VESSEL REGISTER'!$E$6:$E$105,"<"&DATE(YEAR(TODAY()),MONTH(TODAY())-3,1)) | K24: =COUNTIFS('VESSEL REGISTER'!$G$6:$G$105,">="&DATE(YEAR(TODAY()),MONTH(TODAY())-4,1),'VESSEL REGISTER'!$G$6:$G$105,"<"&DATE(YEAR(TODAY()),MONTH(TODAY())-3,1)) | L24: =SUMIFS('VESSEL REGISTER'!$F$6:$F$105,'VESSEL REGISTER'!$G$6:$G$105,">="&DATE(YEAR(TODAY()),MONTH(TODAY())-4,1),'VESSEL REGISTER'!$G$6:$G$105,"<"&DATE(YEAR(TODAY()),MONTH(TODAY())-3,1))
A25: ='GUIDE & SETTINGS'!F6 | D25: =COUNTIFS('VESSEL REGISTER'!$H$6:$H$105,"PENDING",'VESSEL REGISTER'!$K$6:$K$105,A25) | E25: =SUMIFS('VESSEL REGISTER'!$F$6:$F$105,'VESSEL REGISTER'!$H$6:$H$105,"PENDING",'VESSEL REGISTER'!$K$6:$K$105,A25) | F25: =IF($E$6=0,0,D25/$E$6) | G25: =IF(D25=0,0,SUMPRODUCT(MAX(('VESSEL REGISTER'!$H$6:$H$105="PENDING")*('VESSEL REGISTER'!$K$6:$K$105=A25)*N(+'VESSEL REGISTER'!$I$6:$I$105)))) | I25: =TEXT(DATE(YEAR(TODAY()),MONTH(TODAY())-3,1),"mmm yy") | J25: =COUNTIFS('VESSEL REGISTER'!$E$6:$E$105,">="&DATE(YEAR(TODAY()),MONTH(TODAY())-3,1),'VESSEL REGISTER'!$E$6:$E$105,"<"&DATE(YEAR(TODAY()),MONTH(TODAY())-2,1)) | K25: =COUNTIFS('VESSEL REGISTER'!$G$6:$G$105,">="&DATE(YEAR(TODAY()),MONTH(TODAY())-3,1),'VESSEL REGISTER'!$G$6:$G$105,"<"&DATE(YEAR(TODAY()),MONTH(TODAY())-2,1)) | L25: =SUMIFS('VESSEL REGISTER'!$F$6:$F$105,'VESSEL REGISTER'!$G$6:$G$105,">="&DATE(YEAR(TODAY()),MONTH(TODAY())-3,1),'VESSEL REGISTER'!$G$6:$G$105,"<"&DATE(YEAR(TODAY()),MONTH(TODAY())-2,1))
A26: ='GUIDE & SETTINGS'!F7 | D26: =COUNTIFS('VESSEL REGISTER'!$H$6:$H$105,"PENDING",'VESSEL REGISTER'!$K$6:$K$105,A26) | E26: =SUMIFS('VESSEL REGISTER'!$F$6:$F$105,'VESSEL REGISTER'!$H$6:$H$105,"PENDING",'VESSEL REGISTER'!$K$6:$K$105,A26) | F26: =IF($E$6=0,0,D26/$E$6) | G26: =IF(D26=0,0,SUMPRODUCT(MAX(('VESSEL REGISTER'!$H$6:$H$105="PENDING")*('VESSEL REGISTER'!$K$6:$K$105=A26)*N(+'VESSEL REGISTER'!$I$6:$I$105)))) | I26: =TEXT(DATE(YEAR(TODAY()),MONTH(TODAY())-2,1),"mmm yy") | J26: =COUNTIFS('VESSEL REGISTER'!$E$6:$E$105,">="&DATE(YEAR(TODAY()),MONTH(TODAY())-2,1),'VESSEL REGISTER'!$E$6:$E$105,"<"&DATE(YEAR(TODAY()),MONTH(TODAY())-1,1)) | K26: =COUNTIFS('VESSEL REGISTER'!$G$6:$G$105,">="&DATE(YEAR(TODAY()),MONTH(TODAY())-2,1),'VESSEL REGISTER'!$G$6:$G$105,"<"&DATE(YEAR(TODAY()),MONTH(TODAY())-1,1)) | L26: =SUMIFS('VESSEL REGISTER'!$F$6:$F$105,'VESSEL REGISTER'!$G$6:$G$105,">="&DATE(YEAR(TODAY()),MONTH(TODAY())-2,1),'VESSEL REGISTER'!$G$6:$G$105,"<"&DATE(YEAR(TODAY()),MONTH(TODAY())-1,1))
A27: ='GUIDE & SETTINGS'!F8 | D27: =COUNTIFS('VESSEL REGISTER'!$H$6:$H$105,"PENDING",'VESSEL REGISTER'!$K$6:$K$105,A27) | E27: =SUMIFS('VESSEL REGISTER'!$F$6:$F$105,'VESSEL REGISTER'!$H$6:$H$105,"PENDING",'VESSEL REGISTER'!$K$6:$K$105,A27) | F27: =IF($E$6=0,0,D27/$E$6) | G27: =IF(D27=0,0,SUMPRODUCT(MAX(('VESSEL REGISTER'!$H$6:$H$105="PENDING")*('VESSEL REGISTER'!$K$6:$K$105=A27)*N(+'VESSEL REGISTER'!$I$6:$I$105)))) | I27: =TEXT(DATE(YEAR(TODAY()),MONTH(TODAY())-1,1),"mmm yy") | J27: =COUNTIFS('VESSEL REGISTER'!$E$6:$E$105,">="&DATE(YEAR(TODAY()),MONTH(TODAY())-1,1),'VESSEL REGISTER'!$E$6:$E$105,"<"&DATE(YEAR(TODAY()),MONTH(TODAY())-0,1)) | K27: =COUNTIFS('VESSEL REGISTER'!$G$6:$G$105,">="&DATE(YEAR(TODAY()),MONTH(TODAY())-1,1),'VESSEL REGISTER'!$G$6:$G$105,"<"&DATE(YEAR(TODAY()),MONTH(TODAY())-0,1)) | L27: =SUMIFS('VESSEL REGISTER'!$F$6:$F$105,'VESSEL REGISTER'!$G$6:$G$105,">="&DATE(YEAR(TODAY()),MONTH(TODAY())-1,1),'VESSEL REGISTER'!$G$6:$G$105,"<"&DATE(YEAR(TODAY()),MONTH(TODAY())-0,1))
A28: ='GUIDE & SETTINGS'!F9 | D28: =COUNTIFS('VESSEL REGISTER'!$H$6:$H$105,"PENDING",'VESSEL REGISTER'!$K$6:$K$105,A28) | E28: =SUMIFS('VESSEL REGISTER'!$F$6:$F$105,'VESSEL REGISTER'!$H$6:$H$105,"PENDING",'VESSEL REGISTER'!$K$6:$K$105,A28) | F28: =IF($E$6=0,0,D28/$E$6) | G28: =IF(D28=0,0,SUMPRODUCT(MAX(('VESSEL REGISTER'!$H$6:$H$105="PENDING")*('VESSEL REGISTER'!$K$6:$K$105=A28)*N(+'VESSEL REGISTER'!$I$6:$I$105)))) | I28: =TEXT(DATE(YEAR(TODAY()),MONTH(TODAY())-0,1),"mmm yy") | J28: =COUNTIFS('VESSEL REGISTER'!$E$6:$E$105,">="&DATE(YEAR(TODAY()),MONTH(TODAY())-0,1),'VESSEL REGISTER'!$E$6:$E$105,"<"&DATE(YEAR(TODAY()),MONTH(TODAY())--1,1)) | K28: =COUNTIFS('VESSEL REGISTER'!$G$6:$G$105,">="&DATE(YEAR(TODAY()),MONTH(TODAY())-0,1),'VESSEL REGISTER'!$G$6:$G$105,"<"&DATE(YEAR(TODAY()),MONTH(TODAY())--1,1)) | L28: =SUMIFS('VESSEL REGISTER'!$F$6:$F$105,'VESSEL REGISTER'!$G$6:$G$105,">="&DATE(YEAR(TODAY()),MONTH(TODAY())-0,1),'VESSEL REGISTER'!$G$6:$G$105,"<"&DATE(YEAR(TODAY()),MONTH(TODAY())--1,1))
A29: Reason not stated | D29: =$E$6-SUM(D23:D28) | E29: =$I$6-SUM(E23:E28) | F29: =IF($E$6=0,0,D29/$E$6)
A31: VISUAL OVERVIEW
A48: PENDING VESSELS - OLDEST FIRST (ACTION LIST)
A49: # | B49: Vessel | D49: Product | E49: Qty (MT) | F49: Days pending | G49: Ageing | H49: Pending reason | J49: Outstanding items / remarks | L49: Action owner
A50: =IF(ISNUMBER(MATCH(1,'VESSEL REGISTER'!$O$6:$O$105,0)),1,"") | B50: =IF(ISNUMBER(MATCH(1,'VESSEL REGISTER'!$O$6:$O$105,0)),INDEX('VESSEL REGISTER'!$B$6:$B$105,MATCH(1,'VESSEL REGISTER'!$O$6:$O$105,0))&"","") | D50: =IF(ISNUMBER(MATCH(1,'VESSEL REGISTER'!$O$6:$O$105,0)),INDEX('VESSEL REGISTER'!$C$6:$C$105,MATCH(1,'VESSEL REGISTER'!$O$6:$O$105,0))&"","") | E50: =IF(ISNUMBER(MATCH(1,'VESSEL REGISTER'!$O$6:$O$105,0)),INDEX('VESSEL REGISTER'!$F$6:$F$105,MATCH(1,'VESSEL REGISTER'!$O$6:$O$105,0)),"") | F50: =IF(ISNUMBER(MATCH(1,'VESSEL REGISTER'!$O$6:$O$105,0)),INDEX('VESSEL REGISTER'!$I$6:$I$105,MATCH(1,'VESSEL REGISTER'!$O$6:$O$105,0)),"") | G50: =IF(ISNUMBER(MATCH(1,'VESSEL REGISTER'!$O$6:$O$105,0)),INDEX('VESSEL REGISTER'!$J$6:$J$105,MATCH(1,'VESSEL REGISTER'!$O$6:$O$105,0))&"","") | H50: =IF(ISNUMBER(MATCH(1,'VESSEL REGISTER'!$O$6:$O$105,0)),INDEX('VESSEL REGISTER'!$K$6:$K$105,MATCH(1,'VESSEL REGISTER'!$O$6:$O$105,0))&"","") | J50: =IF(ISNUMBER(MATCH(1,'VESSEL REGISTER'!$O$6:$O$105,0)),INDEX('VESSEL REGISTER'!$L$6:$L$105,MATCH(1,'VESSEL REGISTER'!$O$6:$O$105,0))&"","") | L50: =IF(ISNUMBER(MATCH(1,'VESSEL REGISTER'!$O$6:$O$105,0)),INDEX('VESSEL REGISTER'!$M$6:$M$105,MATCH(1,'VESSEL REGISTER'!$O$6:$O$105,0))&"","")
A51: =IF(ISNUMBER(MATCH(2,'VESSEL REGISTER'!$O$6:$O$105,0)),2,"") | B51: =IF(ISNUMBER(MATCH(2,'VESSEL REGISTER'!$O$6:$O$105,0)),INDEX('VESSEL REGISTER'!$B$6:$B$105,MATCH(2,'VESSEL REGISTER'!$O$6:$O$105,0))&"","") | D51: =IF(ISNUMBER(MATCH(2,'VESSEL REGISTER'!$O$6:$O$105,0)),INDEX('VESSEL REGISTER'!$C$6:$C$105,MATCH(2,'VESSEL REGISTER'!$O$6:$O$105,0))&"","") | E51: =IF(ISNUMBER(MATCH(2,'VESSEL REGISTER'!$O$6:$O$105,0)),INDEX('VESSEL REGISTER'!$F$6:$F$105,MATCH(2,'VESSEL REGISTER'!$O$6:$O$105,0)),"") | F51: =IF(ISNUMBER(MATCH(2,'VESSEL REGISTER'!$O$6:$O$105,0)),INDEX('VESSEL REGISTER'!$I$6:$I$105,MATCH(2,'VESSEL REGISTER'!$O$6:$O$105,0)),"") | G51: =IF(ISNUMBER(MATCH(2,'VESSEL REGISTER'!$O$6:$O$105,0)),INDEX('VESSEL REGISTER'!$J$6:$J$105,MATCH(2,'VESSEL REGISTER'!$O$6:$O$105,0))&"","") | H51: =IF(ISNUMBER(MATCH(2,'VESSEL REGISTER'!$O$6:$O$105,0)),INDEX('VESSEL REGISTER'!$K$6:$K$105,MATCH(2,'VESSEL REGISTER'!$O$6:$O$105,0))&"","") | J51: =IF(ISNUMBER(MATCH(2,'VESSEL REGISTER'!$O$6:$O$105,0)),INDEX('VESSEL REGISTER'!$L$6:$L$105,MATCH(2,'VESSEL REGISTER'!$O$6:$O$105,0))&"","") | L51: =IF(ISNUMBER(MATCH(2,'VESSEL REGISTER'!$O$6:$O$105,0)),INDEX('VESSEL REGISTER'!$M$6:$M$105,MATCH(2,'VESSEL REGISTER'!$O$6:$O$105,0))&"","")
A52: =IF(ISNUMBER(MATCH(3,'VESSEL REGISTER'!$O$6:$O$105,0)),3,"") | B52: =IF(ISNUMBER(MATCH(3,'VESSEL REGISTER'!$O$6:$O$105,0)),INDEX('VESSEL REGISTER'!$B$6:$B$105,MATCH(3,'VESSEL REGISTER'!$O$6:$O$105,0))&"","") | D52: =IF(ISNUMBER(MATCH(3,'VESSEL REGISTER'!$O$6:$O$105,0)),INDEX('VESSEL REGISTER'!$C$6:$C$105,MATCH(3,'VESSEL REGISTER'!$O$6:$O$105,0))&"","") | E52: =IF(ISNUMBER(MATCH(3,'VESSEL REGISTER'!$O$6:$O$105,0)),INDEX('VESSEL REGISTER'!$F$6:$F$105,MATCH(3,'VESSEL REGISTER'!$O$6:$O$105,0)),"") | F52: =IF(ISNUMBER(MATCH(3,'VESSEL REGISTER'!$O$6:$O$105,0)),INDEX('VESSEL REGISTER'!$I$6:$I$105,MATCH(3,'VESSEL REGISTER'!$O$6:$O$105,0)),"") | G52: =IF(ISNUMBER(MATCH(3,'VESSEL REGISTER'!$O$6:$O$105,0)),INDEX('VESSEL REGISTER'!$J$6:$J$105,MATCH(3,'VESSEL REGISTER'!$O$6:$O$105,0))&"","") | H52: =IF(ISNUMBER(MATCH(3,'VESSEL REGISTER'!$O$6:$O$105,0)),INDEX('VESSEL REGISTER'!$K$6:$K$105,MATCH(3,'VESSEL REGISTER'!$O$6:$O$105,0))&"","") | J52: =IF(ISNUMBER(MATCH(3,'VESSEL REGISTER'!$O$6:$O$105,0)),INDEX('VESSEL REGISTER'!$L$6:$L$105,MATCH(3,'VESSEL REGISTER'!$O$6:$O$105,0))&"","") | L52: =IF(ISNUMBER(MATCH(3,'VESSEL REGISTER'!$O$6:$O$105,0)),INDEX('VESSEL REGISTER'!$M$6:$M$105,MATCH(3,'VESSEL REGISTER'!$O$6:$O$105,0))&"","")
A53: =IF(ISNUMBER(MATCH(4,'VESSEL REGISTER'!$O$6:$O$105,0)),4,"") | B53: =IF(ISNUMBER(MATCH(4,'VESSEL REGISTER'!$O$6:$O$105,0)),INDEX('VESSEL REGISTER'!$B$6:$B$105,MATCH(4,'VESSEL REGISTER'!$O$6:$O$105,0))&"","") | D53: =IF(ISNUMBER(MATCH(4,'VESSEL REGISTER'!$O$6:$O$105,0)),INDEX('VESSEL REGISTER'!$C$6:$C$105,MATCH(4,'VESSEL REGISTER'!$O$6:$O$105,0))&"","") | E53: =IF(ISNUMBER(MATCH(4,'VESSEL REGISTER'!$O$6:$O$105,0)),INDEX('VESSEL REGISTER'!$F$6:$F$105,MATCH(4,'VESSEL REGISTER'!$O$6:$O$105,0)),"") | F53: =IF(ISNUMBER(MATCH(4,'VESSEL REGISTER'!$O$6:$O$105,0)),INDEX('VESSEL REGISTER'!$I$6:$I$105,MATCH(4,'VESSEL REGISTER'!$O$6:$O$105,0)),"") | G53: =IF(ISNUMBER(MATCH(4,'VESSEL REGISTER'!$O$6:$O$105,0)),INDEX('VESSEL REGISTER'!$J$6:$J$105,MATCH(4,'VESSEL REGISTER'!$O$6:$O$105,0))&"","") | H53: =IF(ISNUMBER(MATCH(4,'VESSEL REGISTER'!$O$6:$O$105,0)),INDEX('VESSEL REGISTER'!$K$6:$K$105,MATCH(4,'VESSEL REGISTER'!$O$6:$O$105,0))&"","") | J53: =IF(ISNUMBER(MATCH(4,'VESSEL REGISTER'!$O$6:$O$105,0)),INDEX('VESSEL REGISTER'!$L$6:$L$105,MATCH(4,'VESSEL REGISTER'!$O$6:$O$105,0))&"","") | L53: =IF(ISNUMBER(MATCH(4,'VESSEL REGISTER'!$O$6:$O$105,0)),INDEX('VESSEL REGISTER'!$M$6:$M$105,MATCH(4,'VESSEL REGISTER'!$O$6:$O$105,0))&"","")
A54: =IF(ISNUMBER(MATCH(5,'VESSEL REGISTER'!$O$6:$O$105,0)),5,"") | B54: =IF(ISNUMBER(MATCH(5,'VESSEL REGISTER'!$O$6:$O$105,0)),INDEX('VESSEL REGISTER'!$B$6:$B$105,MATCH(5,'VESSEL REGISTER'!$O$6:$O$105,0))&"","") | D54: =IF(ISNUMBER(MATCH(5,'VESSEL REGISTER'!$O$6:$O$105,0)),INDEX('VESSEL REGISTER'!$C$6:$C$105,MATCH(5,'VESSEL REGISTER'!$O$6:$O$105,0))&"","") | E54: =IF(ISNUMBER(MATCH(5,'VESSEL REGISTER'!$O$6:$O$105,0)),INDEX('VESSEL REGISTER'!$F$6:$F$105,MATCH(5,'VESSEL REGISTER'!$O$6:$O$105,0)),"") | F54: =IF(ISNUMBER(MATCH(5,'VESSEL REGISTER'!$O$6:$O$105,0)),INDEX('VESSEL REGISTER'!$I$6:$I$105,MATCH(5,'VESSEL REGISTER'!$O$6:$O$105,0)),"") | G54: =IF(ISNUMBER(MATCH(5,'VESSEL REGISTER'!$O$6:$O$105,0)),INDEX('VESSEL REGISTER'!$J$6:$J$105,MATCH(5,'VESSEL REGISTER'!$O$6:$O$105,0))&"","") | H54: =IF(ISNUMBER(MATCH(5,'VESSEL REGISTER'!$O$6:$O$105,0)),INDEX('VESSEL REGISTER'!$K$6:$K$105,MATCH(5,'VESSEL REGISTER'!$O$6:$O$105,0))&"","") | J54: =IF(ISNUMBER(MATCH(5,'VESSEL REGISTER'!$O$6:$O$105,0)),INDEX('VESSEL REGISTER'!$L$6:$L$105,MATCH(5,'VESSEL REGISTER'!$O$6:$O$105,0))&"","") | L54: =IF(ISNUMBER(MATCH(5,'VESSEL REGISTER'!$O$6:$O$105,0)),INDEX('VESSEL REGISTER'!$M$6:$M$105,MATCH(5,'VESSEL REGISTER'!$O$6:$O$105,0))&"","")
A55: =IF(ISNUMBER(MATCH(6,'VESSEL REGISTER'!$O$6:$O$105,0)),6,"") | B55: =IF(ISNUMBER(MATCH(6,'VESSEL REGISTER'!$O$6:$O$105,0)),INDEX('VESSEL REGISTER'!$B$6:$B$105,MATCH(6,'VESSEL REGISTER'!$O$6:$O$105,0))&"","") | D55: =IF(ISNUMBER(MATCH(6,'VESSEL REGISTER'!$O$6:$O$105,0)),INDEX('VESSEL REGISTER'!$C$6:$C$105,MATCH(6,'VESSEL REGISTER'!$O$6:$O$105,0))&"","") | E55: =IF(ISNUMBER(MATCH(6,'VESSEL REGISTER'!$O$6:$O$105,0)),INDEX('VESSEL REGISTER'!$F$6:$F$105,MATCH(6,'VESSEL REGISTER'!$O$6:$O$105,0)),"") | F55: =IF(ISNUMBER(MATCH(6,'VESSEL REGISTER'!$O$6:$O$105,0)),INDEX('VESSEL REGISTER'!$I$6:$I$105,MATCH(6,'VESSEL REGISTER'!$O$6:$O$105,0)),"") | G55: =IF(ISNUMBER(MATCH(6,'VESSEL REGISTER'!$O$6:$O$105,0)),INDEX('VESSEL REGISTER'!$J$6:$J$105,MATCH(6,'VESSEL REGISTER'!$O$6:$O$105,0))&"","") | H55: =IF(ISNUMBER(MATCH(6,'VESSEL REGISTER'!$O$6:$O$105,0)),INDEX('VESSEL REGISTER'!$K$6:$K$105,MATCH(6,'VESSEL REGISTER'!$O$6:$O$105,0))&"","") | J55: =IF(ISNUMBER(MATCH(6,'VESSEL REGISTER'!$O$6:$O$105,0)),INDEX('VESSEL REGISTER'!$L$6:$L$105,MATCH(6,'VESSEL REGISTER'!$O$6:$O$105,0))&"","") | L55: =IF(ISNUMBER(MATCH(6,'VESSEL REGISTER'!$O$6:$O$105,0)),INDEX('VESSEL REGISTER'!$M$6:$M$105,MATCH(6,'VESSEL REGISTER'!$O$6:$O$105,0))&"","")
A56: =IF(ISNUMBER(MATCH(7,'VESSEL REGISTER'!$O$6:$O$105,0)),7,"") | B56: =IF(ISNUMBER(MATCH(7,'VESSEL REGISTER'!$O$6:$O$105,0)),INDEX('VESSEL REGISTER'!$B$6:$B$105,MATCH(7,'VESSEL REGISTER'!$O$6:$O$105,0))&"","") | D56: =IF(ISNUMBER(MATCH(7,'VESSEL REGISTER'!$O$6:$O$105,0)),INDEX('VESSEL REGISTER'!$C$6:$C$105,MATCH(7,'VESSEL REGISTER'!$O$6:$O$105,0))&"","") | E56: =IF(ISNUMBER(MATCH(7,'VESSEL REGISTER'!$O$6:$O$105,0)),INDEX('VESSEL REGISTER'!$F$6:$F$105,MATCH(7,'VESSEL REGISTER'!$O$6:$O$105,0)),"") | F56: =IF(ISNUMBER(MATCH(7,'VESSEL REGISTER'!$O$6:$O$105,0)),INDEX('VESSEL REGISTER'!$I$6:$I$105,MATCH(7,'VESSEL REGISTER'!$O$6:$O$105,0)),"") | G56: =IF(ISNUMBER(MATCH(7,'VESSEL REGISTER'!$O$6:$O$105,0)),INDEX('VESSEL REGISTER'!$J$6:$J$105,MATCH(7,'VESSEL REGISTER'!$O$6:$O$105,0))&"","") | H56: =IF(ISNUMBER(MATCH(7,'VESSEL REGISTER'!$O$6:$O$105,0)),INDEX('VESSEL REGISTER'!$K$6:$K$105,MATCH(7,'VESSEL REGISTER'!$O$6:$O$105,0))&"","") | J56: =IF(ISNUMBER(MATCH(7,'VESSEL REGISTER'!$O$6:$O$105,0)),INDEX('VESSEL REGISTER'!$L$6:$L$105,MATCH(7,'VESSEL REGISTER'!$O$6:$O$105,0))&"","") | L56: =IF(ISNUMBER(MATCH(7,'VESSEL REGISTER'!$O$6:$O$105,0)),INDEX('VESSEL REGISTER'!$M$6:$M$105,MATCH(7,'VESSEL REGISTER'!$O$6:$O$105,0))&"","")
A57: =IF(ISNUMBER(MATCH(8,'VESSEL REGISTER'!$O$6:$O$105,0)),8,"") | B57: =IF(ISNUMBER(MATCH(8,'VESSEL REGISTER'!$O$6:$O$105,0)),INDEX('VESSEL REGISTER'!$B$6:$B$105,MATCH(8,'VESSEL REGISTER'!$O$6:$O$105,0))&"","") | D57: =IF(ISNUMBER(MATCH(8,'VESSEL REGISTER'!$O$6:$O$105,0)),INDEX('VESSEL REGISTER'!$C$6:$C$105,MATCH(8,'VESSEL REGISTER'!$O$6:$O$105,0))&"","") | E57: =IF(ISNUMBER(MATCH(8,'VESSEL REGISTER'!$O$6:$O$105,0)),INDEX('VESSEL REGISTER'!$F$6:$F$105,MATCH(8,'VESSEL REGISTER'!$O$6:$O$105,0)),"") | F57: =IF(ISNUMBER(MATCH(8,'VESSEL REGISTER'!$O$6:$O$105,0)),INDEX('VESSEL REGISTER'!$I$6:$I$105,MATCH(8,'VESSEL REGISTER'!$O$6:$O$105,0)),"") | G57: =IF(ISNUMBER(MATCH(8,'VESSEL REGISTER'!$O$6:$O$105,0)),INDEX('VESSEL REGISTER'!$J$6:$J$105,MATCH(8,'VESSEL REGISTER'!$O$6:$O$105,0))&"","") | H57: =IF(ISNUMBER(MATCH(8,'VESSEL REGISTER'!$O$6:$O$105,0)),INDEX('VESSEL REGISTER'!$K$6:$K$105,MATCH(8,'VESSEL REGISTER'!$O$6:$O$105,0))&"","") | J57: =IF(ISNUMBER(MATCH(8,'VESSEL REGISTER'!$O$6:$O$105,0)),INDEX('VESSEL REGISTER'!$L$6:$L$105,MATCH(8,'VESSEL REGISTER'!$O$6:$O$105,0))&"","") | L57: =IF(ISNUMBER(MATCH(8,'VESSEL REGISTER'!$O$6:$O$105,0)),INDEX('VESSEL REGISTER'!$M$6:$M$105,MATCH(8,'VESSEL REGISTER'!$O$6:$O$105,0))&"","")
A58: =IF(ISNUMBER(MATCH(9,'VESSEL REGISTER'!$O$6:$O$105,0)),9,"") | B58: =IF(ISNUMBER(MATCH(9,'VESSEL REGISTER'!$O$6:$O$105,0)),INDEX('VESSEL REGISTER'!$B$6:$B$105,MATCH(9,'VESSEL REGISTER'!$O$6:$O$105,0))&"","") | D58: =IF(ISNUMBER(MATCH(9,'VESSEL REGISTER'!$O$6:$O$105,0)),INDEX('VESSEL REGISTER'!$C$6:$C$105,MATCH(9,'VESSEL REGISTER'!$O$6:$O$105,0))&"","") | E58: =IF(ISNUMBER(MATCH(9,'VESSEL REGISTER'!$O$6:$O$105,0)),INDEX('VESSEL REGISTER'!$F$6:$F$105,MATCH(9,'VESSEL REGISTER'!$O$6:$O$105,0)),"") | F58: =IF(ISNUMBER(MATCH(9,'VESSEL REGISTER'!$O$6:$O$105,0)),INDEX('VESSEL REGISTER'!$I$6:$I$105,MATCH(9,'VESSEL REGISTER'!$O$6:$O$105,0)),"") | G58: =IF(ISNUMBER(MATCH(9,'VESSEL REGISTER'!$O$6:$O$105,0)),INDEX('VESSEL REGISTER'!$J$6:$J$105,MATCH(9,'VESSEL REGISTER'!$O$6:$O$105,0))&"","") | H58: =IF(ISNUMBER(MATCH(9,'VESSEL REGISTER'!$O$6:$O$105,0)),INDEX('VESSEL REGISTER'!$K$6:$K$105,MATCH(9,'VESSEL REGISTER'!$O$6:$O$105,0))&"","") | J58: =IF(ISNUMBER(MATCH(9,'VESSEL REGISTER'!$O$6:$O$105,0)),INDEX('VESSEL REGISTER'!$L$6:$L$105,MATCH(9,'VESSEL REGISTER'!$O$6:$O$105,0))&"","") | L58: =IF(ISNUMBER(MATCH(9,'VESSEL REGISTER'!$O$6:$O$105,0)),INDEX('VESSEL REGISTER'!$M$6:$M$105,MATCH(9,'VESSEL REGISTER'!$O$6:$O$105,0))&"","")
A59: =IF(ISNUMBER(MATCH(10,'VESSEL REGISTER'!$O$6:$O$105,0)),10,"") | B59: =IF(ISNUMBER(MATCH(10,'VESSEL REGISTER'!$O$6:$O$105,0)),INDEX('VESSEL REGISTER'!$B$6:$B$105,MATCH(10,'VESSEL REGISTER'!$O$6:$O$105,0))&"","") | D59: =IF(ISNUMBER(MATCH(10,'VESSEL REGISTER'!$O$6:$O$105,0)),INDEX('VESSEL REGISTER'!$C$6:$C$105,MATCH(10,'VESSEL REGISTER'!$O$6:$O$105,0))&"","") | E59: =IF(ISNUMBER(MATCH(10,'VESSEL REGISTER'!$O$6:$O$105,0)),INDEX('VESSEL REGISTER'!$F$6:$F$105,MATCH(10,'VESSEL REGISTER'!$O$6:$O$105,0)),"") | F59: =IF(ISNUMBER(MATCH(10,'VESSEL REGISTER'!$O$6:$O$105,0)),INDEX('VESSEL REGISTER'!$I$6:$I$105,MATCH(10,'VESSEL REGISTER'!$O$6:$O$105,0)),"") | G59: =IF(ISNUMBER(MATCH(10,'VESSEL REGISTER'!$O$6:$O$105,0)),INDEX('VESSEL REGISTER'!$J$6:$J$105,MATCH(10,'VESSEL REGISTER'!$O$6:$O$105,0))&"","") | H59: =IF(ISNUMBER(MATCH(10,'VESSEL REGISTER'!$O$6:$O$105,0)),INDEX('VESSEL REGISTER'!$K$6:$K$105,MATCH(10,'VESSEL REGISTER'!$O$6:$O$105,0))&"","") | J59: =IF(ISNUMBER(MATCH(10,'VESSEL REGISTER'!$O$6:$O$105,0)),INDEX('VESSEL REGISTER'!$L$6:$L$105,MATCH(10,'VESSEL REGISTER'!$O$6:$O$105,0))&"","") | L59: =IF(ISNUMBER(MATCH(10,'VESSEL REGISTER'!$O$6:$O$105,0)),INDEX('VESSEL REGISTER'!$M$6:$M$105,MATCH(10,'VESSEL REGISTER'!$O$6:$O$105,0))&"","")
A60: =IF(ISNUMBER(MATCH(11,'VESSEL REGISTER'!$O$6:$O$105,0)),11,"") | B60: =IF(ISNUMBER(MATCH(11,'VESSEL REGISTER'!$O$6:$O$105,0)),INDEX('VESSEL REGISTER'!$B$6:$B$105,MATCH(11,'VESSEL REGISTER'!$O$6:$O$105,0))&"","") | D60: =IF(ISNUMBER(MATCH(11,'VESSEL REGISTER'!$O$6:$O$105,0)),INDEX('VESSEL REGISTER'!$C$6:$C$105,MATCH(11,'VESSEL REGISTER'!$O$6:$O$105,0))&"","") | E60: =IF(ISNUMBER(MATCH(11,'VESSEL REGISTER'!$O$6:$O$105,0)),INDEX('VESSEL REGISTER'!$F$6:$F$105,MATCH(11,'VESSEL REGISTER'!$O$6:$O$105,0)),"") | F60: =IF(ISNUMBER(MATCH(11,'VESSEL REGISTER'!$O$6:$O$105,0)),INDEX('VESSEL REGISTER'!$I$6:$I$105,MATCH(11,'VESSEL REGISTER'!$O$6:$O$105,0)),"") | G60: =IF(ISNUMBER(MATCH(11,'VESSEL REGISTER'!$O$6:$O$105,0)),INDEX('VESSEL REGISTER'!$J$6:$J$105,MATCH(11,'VESSEL REGISTER'!$O$6:$O$105,0))&"","") | H60: =IF(ISNUMBER(MATCH(11,'VESSEL REGISTER'!$O$6:$O$105,0)),INDEX('VESSEL REGISTER'!$K$6:$K$105,MATCH(11,'VESSEL REGISTER'!$O$6:$O$105,0))&"","") | J60: =IF(ISNUMBER(MATCH(11,'VESSEL REGISTER'!$O$6:$O$105,0)),INDEX('VESSEL REGISTER'!$L$6:$L$105,MATCH(11,'VESSEL REGISTER'!$O$6:$O$105,0))&"","") | L60: =IF(ISNUMBER(MATCH(11,'VESSEL REGISTER'!$O$6:$O$105,0)),INDEX('VESSEL REGISTER'!$M$6:$M$105,MATCH(11,'VESSEL REGISTER'!$O$6:$O$105,0))&"","")
A61: =IF(ISNUMBER(MATCH(12,'VESSEL REGISTER'!$O$6:$O$105,0)),12,"") | B61: =IF(ISNUMBER(MATCH(12,'VESSEL REGISTER'!$O$6:$O$105,0)),INDEX('VESSEL REGISTER'!$B$6:$B$105,MATCH(12,'VESSEL REGISTER'!$O$6:$O$105,0))&"","") | D61: =IF(ISNUMBER(MATCH(12,'VESSEL REGISTER'!$O$6:$O$105,0)),INDEX('VESSEL REGISTER'!$C$6:$C$105,MATCH(12,'VESSEL REGISTER'!$O$6:$O$105,0))&"","") | E61: =IF(ISNUMBER(MATCH(12,'VESSEL REGISTER'!$O$6:$O$105,0)),INDEX('VESSEL REGISTER'!$F$6:$F$105,MATCH(12,'VESSEL REGISTER'!$O$6:$O$105,0)),"") | F61: =IF(ISNUMBER(MATCH(12,'VESSEL REGISTER'!$O$6:$O$105,0)),INDEX('VESSEL REGISTER'!$I$6:$I$105,MATCH(12,'VESSEL REGISTER'!$O$6:$O$105,0)),"") | G61: =IF(ISNUMBER(MATCH(12,'VESSEL REGISTER'!$O$6:$O$105,0)),INDEX('VESSEL REGISTER'!$J$6:$J$105,MATCH(12,'VESSEL REGISTER'!$O$6:$O$105,0))&"","") | H61: =IF(ISNUMBER(MATCH(12,'VESSEL REGISTER'!$O$6:$O$105,0)),INDEX('VESSEL REGISTER'!$K$6:$K$105,MATCH(12,'VESSEL REGISTER'!$O$6:$O$105,0))&"","") | J61: =IF(ISNUMBER(MATCH(12,'VESSEL REGISTER'!$O$6:$O$105,0)),INDEX('VESSEL REGISTER'!$L$6:$L$105,MATCH(12,'VESSEL REGISTER'!$O$6:$O$105,0))&"","") | L61: =IF(ISNUMBER(MATCH(12,'VESSEL REGISTER'!$O$6:$O$105,0)),INDEX('VESSEL REGISTER'!$M$6:$M$105,MATCH(12,'VESSEL REGISTER'!$O$6:$O$105,0))&"","")
A62: =IF(ISNUMBER(MATCH(13,'VESSEL REGISTER'!$O$6:$O$105,0)),13,"") | B62: =IF(ISNUMBER(MATCH(13,'VESSEL REGISTER'!$O$6:$O$105,0)),INDEX('VESSEL REGISTER'!$B$6:$B$105,MATCH(13,'VESSEL REGISTER'!$O$6:$O$105,0))&"","") | D62: =IF(ISNUMBER(MATCH(13,'VESSEL REGISTER'!$O$6:$O$105,0)),INDEX('VESSEL REGISTER'!$C$6:$C$105,MATCH(13,'VESSEL REGISTER'!$O$6:$O$105,0))&"","") | E62: =IF(ISNUMBER(MATCH(13,'VESSEL REGISTER'!$O$6:$O$105,0)),INDEX('VESSEL REGISTER'!$F$6:$F$105,MATCH(13,'VESSEL REGISTER'!$O$6:$O$105,0)),"") | F62: =IF(ISNUMBER(MATCH(13,'VESSEL REGISTER'!$O$6:$O$105,0)),INDEX('VESSEL REGISTER'!$I$6:$I$105,MATCH(13,'VESSEL REGISTER'!$O$6:$O$105,0)),"") | G62: =IF(ISNUMBER(MATCH(13,'VESSEL REGISTER'!$O$6:$O$105,0)),INDEX('VESSEL REGISTER'!$J$6:$J$105,MATCH(13,'VESSEL REGISTER'!$O$6:$O$105,0))&"","") | H62: =IF(ISNUMBER(MATCH(13,'VESSEL REGISTER'!$O$6:$O$105,0)),INDEX('VESSEL REGISTER'!$K$6:$K$105,MATCH(13,'VESSEL REGISTER'!$O$6:$O$105,0))&"","") | J62: =IF(ISNUMBER(MATCH(13,'VESSEL REGISTER'!$O$6:$O$105,0)),INDEX('VESSEL REGISTER'!$L$6:$L$105,MATCH(13,'VESSEL REGISTER'!$O$6:$O$105,0))&"","") | L62: =IF(ISNUMBER(MATCH(13,'VESSEL REGISTER'!$O$6:$O$105,0)),INDEX('VESSEL REGISTER'!$M$6:$M$105,MATCH(13,'VESSEL REGISTER'!$O$6:$O$105,0))&"","")
...

Sheet VESSEL REGISTER
A1: VESSEL REGISTER - NMDPRA CARGO CLEARANCE TRACKER
A2: Type only in the YELLOW cells. Grey columns calculate automatically. Leave 'Clearance Date' empty while a vessel is pending; enter the date when NMDPRA clears it. Rows marked SAMPLE are examples - overwrite or delete them.
A3: Legend: | B3: You type | C3: Automatic
A5: S/N | B5: VESSEL NAME | C5: BILL OF LADEN DATE | D5: BILL OF LADEN | E5: CERT OF ORIGIN | F5: CARGO MANIFEST | G5: CERT OF QUANTITY | H5: COQ BEFORE LOAD | I5: COQ AFTER LOAD | J5: NOR | K5: NOR-DV/MV | L5: VESSEL SURVEY REPORT BEFORE LOAD | M5: VESSEL SURVEY REPORT AFTRE LOAD | N5: TANK CERT INSPECTION | O5: BUNKER REPORTS | P5: PUMPING LOG
A6: 1 | B6: DEMO VESSEL A | C6: AGO | D6: Apapa | E6: 46223 | F6: 12500 | G6: 46238 | H6: =IF(B6="","",IF(G6<>"","CLEARED","PENDING")) | I6: =IF(OR(B6="",E6=""),"",IF(G6<>"",G6-E6,TODAY()-E6)) | J6: =IF(H6="PENDING",IF(I6="","",IF(I6>'GUIDE & SETTINGS'!$C$7,"CRITICAL",IF(I6>'GUIDE & SETTINGS'!$C$6,"ATTENTION","ON TRACK"))),"") | O6: =IF(AND(H6="PENDING",ISNUMBER(I6)),COUNTIFS($H$6:$H$105,"PENDING",$I$6:$I$105,">"&I6)+COUNTIFS($H$6:H6,"PENDING",$I$6:I6,I6),"") | P6: =IF(B6="","",IF(OR(C6="",E6="",F6=""),"Fill product, start date, qty",IF(AND(G6<>"",G6<E6),"Clearance before start?","OK")))
A7: 2 | B7: DEMO VESSEL B | C7: PMS | D7: Lekki | E7: 46231 | F7: 30000 | G7: 46248 | H7: =IF(B7="","",IF(G7<>"","CLEARED","PENDING")) | I7: =IF(OR(B7="",E7=""),"",IF(G7<>"",G7-E7,TODAY()-E7)) | J7: =IF(H7="PENDING",IF(I7="","",IF(I7>'GUIDE & SETTINGS'!$C$7,"CRITICAL",IF(I7>'GUIDE & SETTINGS'!$C$6,"ATTENTION","ON TRACK"))),"") | O7: =IF(AND(H7="PENDING",ISNUMBER(I7)),COUNTIFS($H$6:$H$105,"PENDING",$I$6:$I$105,">"&I7)+COUNTIFS($H$6:H7,"PENDING",$I$6:I7,I7),"") | P7: =IF(B7="","",IF(OR(C7="",E7="",F7=""),"Fill product, start date, qty",IF(AND(G7<>"",G7<E7),"Clearance before start?","OK")))
A8: 3 | B8: DEMO VESSEL C | C8: AGO | D8: Tin Can | E8: 46246 | F8: 9800.5 | G8: 46265 | H8: =IF(B8="","",IF(G8<>"","CLEARED","PENDING")) | I8: =IF(OR(B8="",E8=""),"",IF(G8<>"",G8-E8,TODAY()-E8)) | J8: =IF(H8="PENDING",IF(I8="","",IF(I8>'GUIDE & SETTINGS'!$C$7,"CRITICAL",IF(I8>'GUIDE & SETTINGS'!$C$6,"ATTENTION","ON TRACK"))),"") | O8: =IF(AND(H8="PENDING",ISNUMBER(I8)),COUNTIFS($H$6:$H$105,"PENDING",$I$6:$I$105,">"&I8)+COUNTIFS($H$6:H8,"PENDING",$I$6:I8,I8),"") | P8: =IF(B8="","",IF(OR(C8="",E8="",F8=""),"Fill product, start date, qty",IF(AND(G8<>"",G8<E8),"Clearance before start?","OK")))
A9: 4 | B9: DEMO VESSEL D | C9: PMS | D9: Apapa | E9: 46262 | F9: 24500.25 | H9: =IF(B9="","",IF(G9<>"","CLEARED","PENDING")) | I9: =IF(OR(B9="",E9=""),"",IF(G9<>"",G9-E9,TODAY()-E9)) | J9: =IF(H9="PENDING",IF(I9="","",IF(I9>'GUIDE & SETTINGS'!$C$7,"CRITICAL",IF(I9>'GUIDE & SETTINGS'!$C$6,"ATTENTION","ON TRACK"))),"") | K9: Submitted - awaiting NMDPRA | L9: Full set filed with NMDPRA; awaiting clearance letter | M9: Operations / NMDPRA liaison | N9: 46304 | O9: =IF(AND(H9="PENDING",ISNUMBER(I9)),COUNTIFS($H$6:$H$105,"PENDING",$I$6:$I$105,">"&I9)+COUNTIFS($H$6:H9,"PENDING",$I$6:I9,I9),"") | P9: =IF(B9="","",IF(OR(C9="",E9="",F9=""),"Fill product, start date, qty",IF(AND(G9<>"",G9<E9),"Clearance before start?","OK")))
A10: 5 | B10: DEMO VESSEL E | C10: AGO | D10: Lekki | E10: 46275 | F10: 15200 | H10: =IF(B10="","",IF(G10<>"","CLEARED","PENDING")) | I10: =IF(OR(B10="",E10=""),"",IF(G10<>"",G10-E10,TODAY()-E10)) | J10: =IF(H10="PENDING",IF(I10="","",IF(I10>'GUIDE & SETTINGS'!$C$7,"CRITICAL",IF(I10>'GUIDE & SETTINGS'!$C$6,"ATTENTION","ON TRACK"))),"") | K10: Awaiting Certificate of Quality | L10: Certificate of Quality, Supplier Letter | M10: Operations / NMDPRA liaison | N10: 46307 | O10: =IF(AND(H10="PENDING",ISNUMBER(I10)),COUNTIFS($H$6:$H$105,"PENDING",$I$6:$I$105,">"&I10)+COUNTIFS($H$6:H10,"PENDING",$I$6:I10,I10),"") | P10: =IF(B10="","",IF(OR(C10="",E10="",F10=""),"Fill product, start date, qty",IF(AND(G10<>"",G10<E10),"Clearance before start?","OK")))
A11: 6 | B11: DEMO VESSEL F | C11: PMS | D11: Tin Can | E11: 46290 | F11: 18750 | H11: =IF(B11="","",IF(G11<>"","CLEARED","PENDING")) | I11: =IF(OR(B11="",E11=""),"",IF(G11<>"",G11-E11,TODAY()-E11)) | J11: =IF(H11="PENDING",IF(I11="","",IF(I11>'GUIDE & SETTINGS'!$C$7,"CRITICAL",IF(I11>'GUIDE & SETTINGS'!$C$6,"ATTENTION","ON TRACK"))),"") | K11: NMDPRA query raised | L11: Query on Ullage Report - corrected copy requested | M11: Operations / NMDPRA liaison | N11: 46303 | O11: =IF(AND(H11="PENDING",ISNUMBER(I11)),COUNTIFS($H$6:$H$105,"PENDING",$I$6:$I$105,">"&I11)+COUNTIFS($H$6:H11,"PENDING",$I$6:I11,I11),"") | P11: =IF(B11="","",IF(OR(C11="",E11="",F11=""),"Fill product, start date, qty",IF(AND(G11<>"",G11<E11),"Clearance before start?","OK")))
A12: 7 | B12: DEMO VESSEL G | C12: AGO | D12: Apapa | E12: 46295 | F12: 11300 | H12: =IF(B12="","",IF(G12<>"","CLEARED","PENDING")) | I12: =IF(OR(B12="",E12=""),"",IF(G12<>"",G12-E12,TODAY()-E12)) | J12: =IF(H12="PENDING",IF(I12="","",IF(I12>'GUIDE & SETTINGS'!$C$7,"CRITICAL",IF(I12>'GUIDE & SETTINGS'!$C$6,"ATTENTION","ON TRACK"))),"") | K12: Awaiting documents | L12: Notice of Readiness, Timesheet | M12: Operations / NMDPRA liaison | N12: 46305 | O12: =IF(AND(H12="PENDING",ISNUMBER(I12)),COUNTIFS($H$6:$H$105,"PENDING",$I$6:$I$105,">"&I12)+COUNTIFS($H$6:H12,"PENDING",$I$6:I12,I12),"") | P12: =IF(B12="","",IF(OR(C12="",E12="",F12=""),"Fill product, start date, qty",IF(AND(G12<>"",G12<E12),"Clearance before start?","OK")))
A13: 8 | H13: =IF(B13="","",IF(G13<>"","CLEARED","PENDING")) | I13: =IF(OR(B13="",E13=""),"",IF(G13<>"",G13-E13,TODAY()-E13)) | J13: =IF(H13="PENDING",IF(I13="","",IF(I13>'GUIDE & SETTINGS'!$C$7,"CRITICAL",IF(I13>'GUIDE & SETTINGS'!$C$6,"ATTENTION","ON TRACK"))),"") | O13: =IF(AND(H13="PENDING",ISNUMBER(I13)),COUNTIFS($H$6:$H$105,"PENDING",$I$6:$I$105,">"&I13)+COUNTIFS($H$6:H13,"PENDING",$I$6:I13,I13),"") | P13: =IF(B13="","",IF(OR(C13="",E13="",F13=""),"Fill product, start date, qty",IF(AND(G13<>"",G13<E13),"Clearance before start?","OK")))
A14: 9 | H14: =IF(B14="","",IF(G14<>"","CLEARED","PENDING")) | I14: =IF(OR(B14="",E14=""),"",IF(G14<>"",G14-E14,TODAY()-E14)) | J14: =IF(H14="PENDING",IF(I14="","",IF(I14>'GUIDE & SETTINGS'!$C$7,"CRITICAL",IF(I14>'GUIDE & SETTINGS'!$C$6,"ATTENTION","ON TRACK"))),"") | O14: =IF(AND(H14="PENDING",ISNUMBER(I14)),COUNTIFS($H$6:$H$105,"PENDING",$I$6:$I$105,">"&I14)+COUNTIFS($H$6:H14,"PENDING",$I$6:I14,I14),"") | P14: =IF(B14="","",IF(OR(C14="",E14="",F14=""),"Fill product, start date, qty",IF(AND(G14<>"",G14<E14),"Clearance before start?","OK")))
A15: 10 | H15: =IF(B15="","",IF(G15<>"","CLEARED","PENDING")) | I15: =IF(OR(B15="",E15=""),"",IF(G15<>"",G15-E15,TODAY()-E15)) | J15: =IF(H15="PENDING",IF(I15="","",IF(I15>'GUIDE & SETTINGS'!$C$7,"CRITICAL",IF(I15>'GUIDE & SETTINGS'!$C$6,"ATTENTION","ON TRACK"))),"") | O15: =IF(AND(H15="PENDING",ISNUMBER(I15)),COUNTIFS($H$6:$H$105,"PENDING",$I$6:$I$105,">"&I15)+COUNTIFS($H$6:H15,"PENDING",$I$6:I15,I15),"") | P15: =IF(B15="","",IF(OR(C15="",E15="",F15=""),"Fill product, start date, qty",IF(AND(G15<>"",G15<E15),"Clearance before start?","OK")))
A16: 11 | H16: =IF(B16="","",IF(G16<>"","CLEARED","PENDING")) | I16: =IF(OR(B16="",E16=""),"",IF(G16<>"",G16-E16,TODAY()-E16)) | J16: =IF(H16="PENDING",IF(I16="","",IF(I16>'GUIDE & SETTINGS'!$C$7,"CRITICAL",IF(I16>'GUIDE & SETTINGS'!$C$6,"ATTENTION","ON TRACK"))),"") | O16: =IF(AND(H16="PENDING",ISNUMBER(I16)),COUNTIFS($H$6:$H$105,"PENDING",$I$6:$I$105,">"&I16)+COUNTIFS($H$6:H16,"PENDING",$I$6:I16,I16),"") | P16: =IF(B16="","",IF(OR(C16="",E16="",F16=""),"Fill product, start date, qty",IF(AND(G16<>"",G16<E16),"Clearance before start?","OK")))
A17: 12 | H17: =IF(B17="","",IF(G17<>"","CLEARED","PENDING")) | I17: =IF(OR(B17="",E17=""),"",IF(G17<>"",G17-E17,TODAY()-E17)) | J17: =IF(H17="PENDING",IF(I17="","",IF(I17>'GUIDE & SETTINGS'!$C$7,"CRITICAL",IF(I17>'GUIDE & SETTINGS'!$C$6,"ATTENTION","ON TRACK"))),"") | O17: =IF(AND(H17="PENDING",ISNUMBER(I17)),COUNTIFS($H$6:$H$105,"PENDING",$I$6:$I$105,">"&I17)+COUNTIFS($H$6:H17,"PENDING",$I$6:I17,I17),"") | P17: =IF(B17="","",IF(OR(C17="",E17="",F17=""),"Fill product, start date, qty",IF(AND(G17<>"",G17<E17),"Clearance before start?","OK")))
A18: 13 | H18: =IF(B18="","",IF(G18<>"","CLEARED","PENDING")) | I18: =IF(OR(B18="",E18=""),"",IF(G18<>"",G18-E18,TODAY()-E18)) | J18: =IF(H18="PENDING",IF(I18="","",IF(I18>'GUIDE & SETTINGS'!$C$7,"CRITICAL",IF(I18>'GUIDE & SETTINGS'!$C$6,"ATTENTION","ON TRACK"))),"") | O18: =IF(AND(H18="PENDING",ISNUMBER(I18)),COUNTIFS($H$6:$H$105,"PENDING",$I$6:$I$105,">"&I18)+COUNTIFS($H$6:H18,"PENDING",$I$6:I18,I18),"") | P18: =IF(B18="","",IF(OR(C18="",E18="",F18=""),"Fill product, start date, qty",IF(AND(G18<>"",G18<E18),"Clearance before start?","OK")))
A19: 14 | H19: =IF(B19="","",IF(G19<>"","CLEARED","PENDING")) | I19: =IF(OR(B19="",E19=""),"",IF(G19<>"",G19-E19,TODAY()-E19)) | J19: =IF(H19="PENDING",IF(I19="","",IF(I19>'GUIDE & SETTINGS'!$C$7,"CRITICAL",IF(I19>'GUIDE & SETTINGS'!$C$6,"ATTENTION","ON TRACK"))),"") | O19: =IF(AND(H19="PENDING",ISNUMBER(I19)),COUNTIFS($H$6:$H$105,"PENDING",$I$6:$I$105,">"&I19)+COUNTIFS($H$6:H19,"PENDING",$I$6:I19,I19),"") | P19: =IF(B19="","",IF(OR(C19="",E19="",F19=""),"Fill product, start date, qty",IF(AND(G19<>"",G19<E19),"Clearance before start?","OK")))
A20: 15 | H20: =IF(B20="","",IF(G20<>"","CLEARED","PENDING")) | I20: =IF(OR(B20="",E20=""),"",IF(G20<>"",G20-E20,TODAY()-E20)) | J20: =IF(H20="PENDING",IF(I20="","",IF(I20>'GUIDE & SETTINGS'!$C$7,"CRITICAL",IF(I20>'GUIDE & SETTINGS'!$C$6,"ATTENTION","ON TRACK"))),"") | O20: =IF(AND(H20="PENDING",ISNUMBER(I20)),COUNTIFS($H$6:$H$105,"PENDING",$I$6:$I$105,">"&I20)+COUNTIFS($H$6:H20,"PENDING",$I$6:I20,I20),"") | P20: =IF(B20="","",IF(OR(C20="",E20="",F20=""),"Fill product, start date, qty",IF(AND(G20<>"",G20<E20),"Clearance before start?","OK")))
A21: 16 | H21: =IF(B21="","",IF(G21<>"","CLEARED","PENDING")) | I21: =IF(OR(B21="",E21=""),"",IF(G21<>"",G21-E21,TODAY()-E21)) | J21: =IF(H21="PENDING",IF(I21="","",IF(I21>'GUIDE & SETTINGS'!$C$7,"CRITICAL",IF(I21>'GUIDE & SETTINGS'!$C$6,"ATTENTION","ON TRACK"))),"") | O21: =IF(AND(H21="PENDING",ISNUMBER(I21)),COUNTIFS($H$6:$H$105,"PENDING",$I$6:$I$105,">"&I21)+COUNTIFS($H$6:H21,"PENDING",$I$6:I21,I21),"") | P21: =IF(B21="","",IF(OR(C21="",E21="",F21=""),"Fill product, start date, qty",IF(AND(G21<>"",G21<E21),"Clearance before start?","OK")))
A22: 17 | H22: =IF(B22="","",IF(G22<>"","CLEARED","PENDING")) | I22: =IF(OR(B22="",E22=""),"",IF(G22<>"",G22-E22,TODAY()-E22)) | J22: =IF(H22="PENDING",IF(I22="","",IF(I22>'GUIDE & SETTINGS'!$C$7,"CRITICAL",IF(I22>'GUIDE & SETTINGS'!$C$6,"ATTENTION","ON TRACK"))),"") | O22: =IF(AND(H22="PENDING",ISNUMBER(I22)),COUNTIFS($H$6:$H$105,"PENDING",$I$6:$I$105,">"&I22)+COUNTIFS($H$6:H22,"PENDING",$I$6:I22,I22),"") | P22: =IF(B22="","",IF(OR(C22="",E22="",F22=""),"Fill product, start date, qty",IF(AND(G22<>"",G22<E22),"Clearance before start?","OK")))
A23: 18 | H23: =IF(B23="","",IF(G23<>"","CLEARED","PENDING")) | I23: =IF(OR(B23="",E23=""),"",IF(G23<>"",G23-E23,TODAY()-E23)) | J23: =IF(H23="PENDING",IF(I23="","",IF(I23>'GUIDE & SETTINGS'!$C$7,"CRITICAL",IF(I23>'GUIDE & SETTINGS'!$C$6,"ATTENTION","ON TRACK"))),"") | O23: =IF(AND(H23="PENDING",ISNUMBER(I23)),COUNTIFS($H$6:$H$105,"PENDING",$I$6:$I$105,">"&I23)+COUNTIFS($H$6:H23,"PENDING",$I$6:I23,I23),"") | P23: =IF(B23="","",IF(OR(C23="",E23="",F23=""),"Fill product, start date, qty",IF(AND(G23<>"",G23<E23),"Clearance before start?","OK")))
A24: 19 | H24: =IF(B24="","",IF(G24<>"","CLEARED","PENDING")) | I24: =IF(OR(B24="",E24=""),"",IF(G24<>"",G24-E24,TODAY()-E24)) | J24: =IF(H24="PENDING",IF(I24="","",IF(I24>'GUIDE & SETTINGS'!$C$7,"CRITICAL",IF(I24>'GUIDE & SETTINGS'!$C$6,"ATTENTION","ON TRACK"))),"") | O24: =IF(AND(H24="PENDING",ISNUMBER(I24)),COUNTIFS($H$6:$H$105,"PENDING",$I$6:$I$105,">"&I24)+COUNTIFS($H$6:H24,"PENDING",$I$6:I24,I24),"") | P24: =IF(B24="","",IF(OR(C24="",E24="",F24=""),"Fill product, start date, qty",IF(AND(G24<>"",G24<E24),"Clearance before start?","OK")))
... A105: 100 | H105: =IF(B105="","",IF(G105<>"","CLEARED","PENDING")) | I105: =IF(OR(B105="",E105=""),"",IF(G105<>"",G105-E105,TODAY()-E105)) | J105: =IF(H105="PENDING",IF(I105="","",IF(I105>'GUIDE & SETTINGS'!$C$7,"CRITICAL",IF(I105>'GUIDE & SETTINGS'!$C$6,"ATTENTION","ON TRACK"))),"") | O105: =IF(AND(H105="PENDING",ISNUMBER(I105)),COUNTIFS($H$6:$H$105,"PENDING",$I$6:$I$105,">"&I105)+COUNTIFS($H$6:H105,"PENDING",$I$6:I105,I105),"") | P105: =IF(B105="","",IF(OR(C105="",E105="",F105=""),"Fill product, start date, qty",IF(AND(G105<>"",G105<E105),"Clearance before start?","OK")))

Sheet GUIDE & SETTINGS
A1: GUIDE & SETTINGS
B3: SETTINGS (yellow cells - edit these) | F3: PENDING REASON LIST (edit wording if needed)
B4: Client | C4: DEMO CLIENT | F4: Awaiting documents
B5: Prepared by | F5: Awaiting Certificate of Quality
B6: Mark as ATTENTION after (days pending) | C6: 7 | F6: Quality query / retest
B7: Mark as CRITICAL after (days pending) | C7: 14 | F7: Submitted - awaiting NMDPRA
F8: NMDPRA query raised
F9: Other
B11: HOW TO USE THIS WORKBOOK - STEP BY STEP
B12: STEP 1 - Open the VESSEL REGISTER sheet. This is the only place you type vessel information. Everything else updates by itself.
B13: STEP 2 - When a new cargo arrives, add one row: vessel name, product (AGO or PMS), port/terminal, the start date (the day the vessel arrived or documents were received) and the B/L quantity in MT.
B14: STEP 3 - While the vessel is NOT yet cleared, leave 'Clearance Date' empty. The status becomes PENDING automatically. Pick a Pending Reason from the list, and write what is still outstanding (for example 'Certificate of Quality, Supplier Letter') and who is responsible.
B15: STEP 4 - When NMDPRA issues the clearance, type the date in 'Clearance Date'. The status changes to CLEARED automatically and the days taken to clear are calculated.
B16: STEP 5 - Open the DASHBOARD sheet to see the full picture: how many vessels are cleared and pending, tonnage, how long vessels have been waiting, why they are waiting, and the action list. It is ready to print or present (landscape, one page wide).
B17: STEP 6 - Every morning, review the 'Pending Vessels - Oldest First' list at the bottom of the dashboard. Red = CRITICAL, amber = ATTENTION.
B19: DEFINITIONS
B20: CLEARED | C20: The cargo has received NMDPRA cargo clearance (a Clearance Date has been entered).
B21: PENDING | C21: The cargo has not yet received NMDPRA clearance (Clearance Date is empty).
B22: Days | C22: For cleared vessels: Clearance Date minus Start Date. For pending vessels: today minus Start Date (the number grows each day).
B23: ON TRACK | C23: Pending for no more than the ATTENTION limit above.
B24: ATTENTION | C24: Pending longer than the ATTENTION limit but not yet past the CRITICAL limit.
B25: CRITICAL | C25: Pending longer than the CRITICAL limit - needs management attention.
B26: Qty (MT) | C26: Bill of Lading quantity in metric tonnes.
B28: NOTE: The SAMPLE vessels (rows marked SAMPLE VESSEL A-G) in the register are illustrative only, so you can see how the dashboard works. Delete or overwrite them with real vessels before presenting to management.
